<robot name="pi_robot">

	<!-- * * * Link Definitions * * * -->

 	<link name="link1">
		<visual>
		    <origin xyz="0 0 0" rpy="0 0 0"/>
			<geometry>
				<box size="0.5 0.5 0.3"/>
			</geometry>
			<material name="Cyan1">
	       		<color rgba="0 0.9 0.9 1.0"/>
	     	</material>
		</visual>	
		<collision>
		<origin xyz="0 0 0" rpy="0 0 0"/>
		<geometry>
		<box size="0.5 0.5 0.3"/>
		</geometry>
		</collision>
		<inertial>
		<origin xyz="0 0 0" rpy="0 0 0"/>
		<mass value="0.5"/>
		<inertia
		ixx="0.1" ixy="0.0" ixz="0.0"
		iyy="0.1" iyz="0.0"
		izz="0.1"/>
		</inertial>
</link>
	

 	<link name="link2">
		<visual>
		    <origin xyz="0 0 0.3" rpy="1.57079633 0 0"/>
			<geometry>
				<cylinder radius="0.2" length="0.3"/>
			</geometry>
			<material name="Black1">
	       		<color rgba="0.2 0.2 0.2 1.0"/>
	     	</material>
		</visual>	

<collision>
		<origin xyz="0 0 0.3" rpy="1.57079633 0 0"/>
		<geometry>
		<cylinder radius="0.2" length="0.3"/>
		</geometry>
		</collision>
		<inertial>
		<origin xyz="0 0 0" rpy="0 0 0"/>
		<mass value="0.5"/>
		<inertia
		ixx="0.1" ixy="0.0" ixz="0.0"
		iyy="0.1" iyz="0.0"
		izz="0.1"/>
</inertial>
	</link>
	
<joint name="base_link__link_01" type="revolute">
    <axis xyz="1 0 0"/>
    <limit effort="1000.0" lower="-3.14" upper="3.14" velocity="0.5"/>
    <origin rpy="0 0 0" xyz="0 0 0"/>
    <parent link="link2"/>
    <child link="link1"/>
</joint>


<transmission name="tran1">
    <type>transmission_interface/SimpleTransmission</type>
    <joint name="base_link__link_01">
      <hardwareInterface>hardware_interface/EffortJointInterface</hardwareInterface>
    </joint>
    <actuator name="motor1">
      <hardwareInterface>hardware_interface/EffortJointInterface</hardwareInterface>
      <mechanicalReduction>1</mechanicalReduction>
    </actuator>
  </transmission>

   <!-- ros_control plugin -->
  <gazebo>
    <plugin name="gazebo_ros_control" filename="libgazebo_ros_control.so">
      <robotNamespace>/rrbot</robotNamespace>
      <robotSimType>gazebo_ros_control/DefaultRobotHWSim</robotSimType>
    </plugin>
  </gazebo>
  
 
</robot>
